2017-08-09 07:22:59
2017-08-10 01:32:06
2017-08-10 18:41:06
2017-08-10 18:45:44
Traceback (most recent call last):
  File "/usr/local/lib/python3.6/shutil.py", line 538, in move
    os.rename(src, real_dst)
FileNotFoundError: [Errno 2] No such file or directory: '/data/code/project_git/common/tsaServer/target/tsaServer' -> '/data/code/project/tsaServer'

During handling of the above exception, another exception occurred:

Traceback (most recent call last):
  File "/root/hyh/cloud/git_get_code.py", line 154, in <module>
    save_cfg_res = save_cfg()
  File "/root/hyh/cloud/git_get_code.py", line 103, in save_cfg
    shutil.move(src_dir,all_app_dir)
  File "/usr/local/lib/python3.6/shutil.py", line 552, in move
    copy_function(src, real_dst)
  File "/usr/local/lib/python3.6/shutil.py", line 251, in copy2
    copyfile(src, dst, follow_symlinks=follow_symlinks)
  File "/usr/local/lib/python3.6/shutil.py", line 114, in copyfile
    with open(src, 'rb') as fsrc:
FileNotFoundError: [Errno 2] No such file or directory: '/data/code/project_git/common/tsaServer/target/tsaServer'
2017-08-10 19:04:29
